Workbook

Sheet USA
A1: Year | B1: Age | C1: qx | D1: lx | E1: ex | F1: dx
A2: 2019 | B2: 18 | C2: 0.00086872457 | D2: 98970.611 | E2: 59.243813 | F2: =D2*C2 -> 85.978202
A3: 2019 | B3: 19 | C3: 0.00095911548 | D3: 98884.633 | E3: 58.294889 | F3: =D3*C3 -> 94.841783
A4: 2019 | B4: 20 | C4: 0.0010736056 | D4: 98789.791 | E4: 57.350374 | F4: =D4*C4 -> 106.06127
A5: 2019 | B5: 21 | C5: 0.0012700903 | D5: 98683.73 | E5: 56.411475 | F5: =D5*C5 -> 125.33725
A6: 2019 | B6: 22 | C6: 0.0013108572 | D6: 98558.393 | E6: 55.482578 | F6: =D6*C6 -> 129.19598
A7: 2019 | B7: 23 | C7: 0.0013522862 | D7: 98429.197 | E7: 54.554747 | F7: =D7*C7 -> 133.10445
A8: 2019 | B8: 24 | C8: 0.0014209055 | D8: 98296.092 | E8: 53.627943 | F8: =D8*C8 -> 139.66946
A9: 2019 | B9: 25 | C9: 0.0015486285 | D9: 98156.423 | E9: 52.70354 | F9: =D9*C9 -> 152.00784
A10: 2019 | B10: 26 | C10: 0.0016237596 | D10: 98004.415 | E10: 51.78451 | F10: =D10*C10 -> 159.13561
A11: 2019 | B11: 27 | C11: 0.0016717868 | D11: 97845.28 | E11: 50.867919 | F11: =D11*C11 -> 163.57645
A12: 2019 | B12: 28 | C12: 0.0017779057 | D12: 97681.703 | E12: 49.952264 | F12: =D12*C12 -> 173.66885
A13: 2019 | B13: 29 | C13: 0.0018402696 | D13: 97508.034 | E13: 49.040342 | F13: =D13*C13 -> 179.44107
... A54: 2019 | B54: 70 | C54: 0.022019808 | D54: 73294.635 | E54: 14.875601 | F54: =D54*C54 -> 1613.9338

Sheet JAPAN
A1: Year | B1: Age | C1: qx | D1: lx | E1: ex | F1: dx
A2: 2019 | B2: 18 | C2: 0.00030237998 | D2: 99587.219 | E2: 63.67796 | F2: =D2*C2 -> 30.113181
A3: 2019 | B3: 19 | C3: 0.0003728711 | D3: 99557.11 | E3: 62.697067 | F3: =D3*C3 -> 37.12197
A4: 2019 | B4: 20 | C4: 0.00042728621 | D4: 99519.995 | E4: 61.720263 | F4: =D4*C4 -> 42.523522
A5: 2019 | B5: 21 | C5: 0.0004779949 | D5: 99477.48 | E5: 60.746427 | F5: =D5*C5 -> 47.549728
A6: 2019 | B6: 22 | C6: 0.0005239111 | D6: 99429.942 | E6: 59.775231 | F6: =D6*C6 -> 52.09245
A7: 2019 | B7: 23 | C7: 0.00045995027 | D7: 99377.863 | E7: 58.806294 | F7: =D7*C7 -> 45.708875
A8: 2019 | B8: 24 | C8: 0.00046318049 | D8: 99332.165 | E8: 57.833119 | F8: =D8*C8 -> 46.008721
A9: 2019 | B9: 25 | C9: 0.00041739046 | D9: 99286.167 | E9: 56.85968 | F9: =D9*C9 -> 41.441099
A10: 2019 | B10: 26 | C10: 0.00043098808 | D10: 99244.734 | E10: 55.883209 | F10: =D10*C10 -> 42.773297
A11: 2019 | B11: 27 | C11: 0.00043777843 | D11: 99201.97 | E11: 54.907084 | F11: =D11*C11 -> 43.428482
A12: 2019 | B12: 28 | C12: 0.00045185689 | D12: 99158.551 | E12: 53.930907 | F12: =D12*C12 -> 44.805474
A13: 2019 | B13: 29 | C13: 0.00052616838 | D13: 99113.756 | E13: 52.955056 | F13: =D13*C13 -> 52.150524
... A54: 2019 | B54: 70 | C54: 0.017291781 | D54: 84045.271 | E54: 15.910232 | F54: =D54*C54 -> 1453.2924

Sheet INDIA
A1: Year | B1: Age | C1: qx | D1: lx | E1: dx
A2: 2006-08 | B2: 18 | C2: 0.0008 | D2: 100000 | E2: =D2*C2 -> 80
A3: 2006-08 | B3: 19 | C3: 0.000848 | D3: =D2*(1-C2) -> 99920 | E3: =D3*C3 -> 84.73216
A4: 2006-08 | B4: 20 | C4: 0.000888 | D4: =D3*(1-C3) -> 99835.268 | E4: =D4*C4 -> 88.653718
A5: 2006-08 | B5: 21 | C5: 0.000919 | D5: =D4*(1-C4) -> 99746.614 | E5: =D5*C5 -> 91.667138
A6: 2006-08 | B6: 22 | C6: 0.000943 | D6: =D5*(1-C5) -> 99654.947 | E6: =D6*C6 -> 93.974615
A7: 2006-08 | B7: 23 | C7: 0.000961 | D7: =D6*(1-C6) -> 99560.972 | E7: =D7*C7 -> 95.678094
A8: 2006-08 | B8: 24 | C8: 0.000974 | D8: =D7*(1-C7) -> 99465.294 | E8: =D8*C8 -> 96.879197
A9: 2006-08 | B9: 25 | C9: 0.000984 | D9: =D8*(1-C8) -> 99368.415 | E9: =D9*C9 -> 97.77852
A10: 2006-08 | B10: 26 | C10: 0.000994 | D10: =D9*(1-C9) -> 99270.637 | E10: =D10*C10 -> 98.675013
A11: 2006-08 | B11: 27 | C11: 0.001004 | D11: =D10*(1-C10) -> 99171.962 | E11: =D11*C11 -> 99.568649
A12: 2006-08 | B12: 28 | C12: 0.001017 | D12: =D11*(1-C11) -> 99072.393 | E12: =D12*C12 -> 100.75662
A13: 2006-08 | B13: 29 | C13: 0.001034 | D13: =D12*(1-C12) -> 98971.636 | E13: =D13*C13 -> 102.33667
A14: 2006-08 | B14: 30 | C14: 0.001056 | D14: =D13*(1-C13) -> 98869.3 | E14: =D14*C14 -> 104.40598
... A54: 2006-08 | B54: 70 | C54: 0.02443 | D54: =D53*(1-C53) -> 74395.041 | E54: =D54*C54 -> 1817.4708

Sheet PREMIUM CALC
A2: Policy Assumptions
A3: Sum Assured | C3: 5000000
A4: Policy Term | C4: 20 | G4: USA | H4: JAPAN | I4: INDIA
A5: Entry Age | C5: 30 | F5: total pv | G5: =SUM(H10:H29) -> 141124.1 | H5: =SUM(H33:H52) -> 52333.703 | I5: =SUM(H56:H75) -> 101455.86
A6: Discount Rate | C6: 0.06 | F6: annuity f | G6: =SUM(G10:G29) -> 11.469921 | H6: =SUM(G33:G52) -> 11.469921 | I6: =SUM(G56:G75) -> 11.469921
F7: net premium | G7: =G5/G6 -> 12303.842 | H7: =H5/H6 -> 4562.6907 | I7: =I5/I6 -> 8845.3842
A9: Year | B9: Age | C9: qx | D9: px | E9: lx | F9: dx | G9: discount f | H9: pv of claims
A10: 1 | B10: 30 | C10: =USA!C14 -> 0.0018906681 | D10: =1-C10 -> 0.99810933 | E10: =USA!D14 -> 97328.593 | F10: =E10*C10 -> 184.01607 | G10: =1/(1+$C$6)^A10 -> 0.94339623 | H10: =($C$3*G10*E10*C10)/$E$10 -> 8918.2459
A11: 2 | B11: 31 | C11: =USA!C15 -> 0.0019133349 | D11: =1-C11 -> 0.99808667 | E11: =USA!D15 -> 97144.577 | F11: =E11*C11 -> 185.87011 | G11: =1/(1+$C$6)^A11 -> 0.88999644 | H11: =($C$3*G11*E11*C11)/$E$10 -> 8498.2083
A12: 3 | B12: 32 | C12: =USA!C16 -> 0.0019245717 | D12: =1-C12 -> 0.99807543 | E12: =USA!D16 -> 96958.707 | F12: =E12*C12 -> 186.60398 | G12: =1/(1+$C$6)^A12 -> 0.83961928 | H12: =($C$3*G12*E12*C12)/$E$10 -> 8048.8321
A13: 4 | B13: 33 | C13: =USA!C17 -> 0.0019698095 | D13: =1-C13 -> 0.99803019 | E13: =USA!D17 -> 96772.103 | F13: =E13*C13 -> 190.62261 | G13: =1/(1+$C$6)^A13 -> 0.79209366 | H13: =($C$3*G13*E13*C13)/$E$10 -> 7756.7626
A14: 5 | B14: 34 | C14: =USA!C18 -> 0.0020816738 | D14: =1-C14 -> 0.99791833 | E14: =USA!D18 -> 96581.48 | F14: =E14*C14 -> 201.05114 | G14: =1/(1+$C$6)^A14 -> 0.74725817 | H14: =($C$3*G14*E14*C14)/$E$10 -> 7718.0354
A15: 6 | B15: 35 | C15: =USA!C19 -> 0.0021542246 | D15: =1-C15 -> 0.99784578 | E15: =USA!D19 -> 96380.429 | F15: =E15*C15 -> 207.62509 | G15: =1/(1+$C$6)^A15 -> 0.70496054 | H15: =($C$3*G15*E15*C15)/$E$10 -> 7519.2446
A16: 7 | B16: 36 | C16: =USA!C20 -> 0.0022017505 | D16: =1-C16 -> 0.99779825 | E16: =USA!D20 -> 96172.804 | F16: =E16*C16 -> 211.74852 | G16: =1/(1+$C$6)^A16 -> 0.66505711 | H16: =($C$3*G16*E16*C16)/$E$10 -> 7234.5062
A17: 8 | B17: 37 | C17: =USA!C21 -> 0.002313046 | D17: =1-C17 -> 0.99768695 | E17: =USA!D21 -> 95961.056 | F17: =E17*C17 -> 221.96234 | G17: =1/(1+$C$6)^A17 -> 0.62741237 | H17: =($C$3*G17*E17*C17)/$E$10 -> 7154.214
A18: 9 | B18: 38 | C18: =USA!C22 -> 0.0024187869 | D18: =1-C18 -> 0.99758121 | E18: =USA!D22 -> 95739.093 | F18: =E18*C18 -> 231.57246 | G18: =1/(1+$C$6)^A18 -> 0.59189846 | H18: =($C$3*G18*E18*C18)/$E$10 -> 7041.4757
A19: 10 | B19: 39 | C19: =USA!C23 -> 0.0024695723 | D19: =1-C19 -> 0.99753043 | E19: =USA!D23 -> 95507.521 | F19: =E19*C19 -> 235.86273 | G19: =1/(1+$C$6)^A19 -> 0.55839478 | H19: =($C$3*G19*E19*C19)/$E$10 -> 6765.9724
A20: 11 | B20: 40 | C20: =USA!C24 -> 0.0027596236 | D20: =1-C20 -> 0.99724038 | E20: =USA!D24 -> 95271.658 | F20: =E20*C20 -> 262.91391 | G20: =1/(1+$C$6)^A20 -> 0.52678753 | H20: =($C$3*G20*E20*C20)/$E$10 -> 7115.0607
A21: 12 | B21: 41 | C21: =USA!C25 -> 0.0026538809 | D21: =1-C21 -> 0.99734612 | E21: =USA!D25 -> 95008.744 | F21: =E21*C21 -> 252.14189 | G21: =1/(1+$C$6)^A21 -> 0.49696936 | H21: =($C$3*G21*E21*C21)/$E$10 -> 6437.3063
... A29: 20 | B29: 49 | C29: =USA!C33 -> 0.0043996868 | D29: =1-C29 -> 0.99560031 | E29: =USA!D33 -> 92543.588 | F29: =E29*C29 -> 407.1628 | G29: =1/(1+$C$6)^A29 -> 0.31180473 | H29: =($C$3*G29*E29*C29)/$E$10 -> 6521.9933
A32: Year | B32: Age | C32: qx | D32: px | E32: lx | F32: dx | G32: discount f | H32: pv of claims
A33: 1 | B33: 30 | C33: =JAPAN!C14 -> 0.00059928758 | D33: =1-C33 -> 0.99940071 | E33: =JAPAN!D14 -> 99061.619 | F33: =E33*C33 -> 59.366398 | G33: =1/(1+$C$6)^A33 -> 0.94339623 | H33: =($C$3*G33*E33*C33)/$E$33 -> 2826.8282
A34: 2 | B34: 31 | C34: =JAPAN!C15 -> 0.00053297449 | D34: =1-C34 -> 0.99946703 | E34: =JAPAN!D15 -> 99002.271 | F34: =E34*C34 -> 52.765685 | G34: =1/(1+$C$6)^A34 -> 0.88999644 | H34: =($C$3*G34*E34*C34)/$E$33 -> 2370.3061
A35: 3 | B35: 32 | C35: =JAPAN!C16 -> 0.00055775634 | D35: =1-C35 -> 0.99944224 | E35: =JAPAN!D16 -> 98949.519 | F35: =E35*C35 -> 55.189721 | G35: =1/(1+$C$6)^A35 -> 0.83961928 | H35: =($C$3*G35*E35*C35)/$E$33 -> 2338.8652
A36: 4 | B36: 33 | C36: =JAPAN!C17 -> 0.00061188422 | D36: =1-C36 -> 0.99938812 | E36: =JAPAN!D17 -> 98894.345 | F36: =E36*C36 -> 60.511889 | G36: =1/(1+$C$6)^A36 -> 0.79209366 | H36: =($C$3*G36*E36*C36)/$E$33 -> 2419.256
A37: 5 | B37: 34 | C37: =JAPAN!C18 -> 0.00062197706 | D37: =1-C37 -> 0.99937802 | E37: =JAPAN!D18 -> 98833.851 | F37: =E37*C37 -> 61.472388 | G37: =1/(1+$C$6)^A37 -> 0.74725817 | H37: =($C$3*G37*E37*C37)/$E$33 -> 2318.544
A38: 6 | B38: 35 | C38: =JAPAN!C19 -> 0.00065034045 | D38: =1-C38 -> 0.99934966 | E38: =JAPAN!D19 -> 98772.398 | F38: =E38*C38 -> 64.235686 | G38: =1/(1+$C$6)^A38 -> 0.70496054 | H38: =($C$3*G38*E38*C38)/$E$33 -> 2285.6291
A39: 7 | B39: 36 | C39: =JAPAN!C20 -> 0.00068829696 | D39: =1-C39 -> 0.9993117 | E39: =JAPAN!D20 -> 98708.183 | F39: =E39*C39 -> 67.940542 | G39: =1/(1+$C$6)^A39 -> 0.66505711 | H39: =($C$3*G39*E39*C39)/$E$33 -> 2280.6179
A40: 8 | B40: 37 | C40: =JAPAN!C21 -> 0.0007434154 | D40: =1-C40 -> 0.99925658 | E40: =JAPAN!D21 -> 98640.266 | F40: =E40*C40 -> 73.330693 | G40: =1/(1+$C$6)^A40 -> 0.62741237 | H40: =($C$3*G40*E40*C40)/$E$33 -> 2322.2205
A41: 9 | B41: 38 | C41: =JAPAN!C22 -> 0.00079909534 | D41: =1-C41 -> 0.9992009 | E41: =JAPAN!D22 -> 98566.963 | F41: =E41*C41 -> 78.7644 | G41: =1/(1+$C$6)^A41 -> 0.59189846 | H41: =($C$3*G41*E41*C41)/$E$33 -> 2353.1075
A42: 10 | B42: 39 | C42: =JAPAN!C23 -> 0.00090145417 | D42: =1-C42 -> 0.99909855 | E42: =JAPAN!D23 -> 98488.23 | F42: =E42*C42 -> 88.782625 | G42: =1/(1+$C$6)^A42 -> 0.55839478 | H42: =($C$3*G42*E42*C42)/$E$33 -> 2502.2685
A43: 11 | B43: 40 | C43: =JAPAN!C24 -> 0.00096669649 | D43: =1-C43 -> 0.9990333 | E43: =JAPAN!D24 -> 98399.487 | F43: =E43*C43 -> 95.122439 | G43: =1/(1+$C$6)^A43 -> 0.52678753 | H43: =($C$3*G43*E43*C43)/$E$33 -> 2529.1992
A44: 12 | B44: 41 | C44: =JAPAN!C25 -> 0.0010009643 | D44: =1-C44 -> 0.99899904 | E44: =JAPAN!D25 -> 98304.41 | F44: =E44*C44 -> 98.399201 | G44: =1/(1+$C$6)^A44 -> 0.49696936 | H44: =($C$3*G44*E44*C44)/$E$33 -> 2468.2308
... A52: 20 | B52: 49 | C52: =JAPAN!C33 -> 0.002212425 | D52: =1-C52 -> 0.99778757 | E52: =JAPAN!D33 -> 97186.059 | F52: =E52*C52 -> 215.01687 | G52: =1/(1+$C$6)^A52 -> 0.31180473 | H52: =($C$3*G52*E52*C52)/$E$33 -> 3383.9179
A55: Year | B55: Age | C55: qx | D55: px | E55: lx | F55: dx | G55: discount f | H55: pv of claims
A56: 1 | B56: 30 | C56: =INDIA!C14 -> 0.001056 | D56: =1-C56 -> 0.998944 | E56: =INDIA!D14 -> 98869.3 | F56: =E56*C56 -> 104.40598 | G56: =1/(1+$C$6)^A56 -> 0.94339623 | H56: =($C$3*G56*E56*C56)/$E$56 -> 4981.1321
A57: 2 | B57: 31 | C57: =INDIA!C15 -> 0.001084 | D57: =1-C57 -> 0.998916 | E57: =INDIA!D15 -> 98764.894 | F57: =E57*C57 -> 107.06114 | G57: =1/(1+$C$6)^A57 -> 0.88999644 | H57: =($C$3*G57*E57*C57)/$E$56 -> 4818.6868
A58: 3 | B58: 32 | C58: =INDIA!C16 -> 0.001119 | D58: =1-C58 -> 0.998881 | E58: =INDIA!D16 -> 98657.832 | F58: =E58*C58 -> 110.39811 | G58: =1/(1+$C$6)^A58 -> 0.83961928 | H58: =($C$3*G58*E58*C58)/$E$56 -> 4687.6223
A59: 4 | B59: 33 | C59: =INDIA!C17 -> 0.001164 | D59: =1-C59 -> 0.998836 | E59: =INDIA!D17 -> 98547.434 | F59: =E59*C59 -> 114.70921 | G59: =1/(1+$C$6)^A59 -> 0.79209366 | H59: =($C$3*G59*E59*C59)/$E$56 -> 4594.9775
A60: 5 | B60: 34 | C60: =INDIA!C18 -> 0.001218 | D60: =1-C60 -> 0.998782 | E60: =INDIA!D18 -> 98432.725 | F60: =E60*C60 -> 119.89106 | G60: =1/(1+$C$6)^A60 -> 0.74725817 | H60: =($C$3*G60*E60*C60)/$E$56 -> 4530.7074
...

Sheet COMPARISON CHART
B2: JAPAN | C2: 4562.6907
B3: INDIA | C3: 8845.3842
B4: USA | C4: 12303.842

Sheet SENSITIVITY
B2: Discount Rate | C2: USA | D2: Japan | E2: India
B3: 0.03 | C3: 12793.505 | D3: 4900.0588 | E3: 9512.0349
B4: 0.04 | C4: 12623.871 | D4: 4782.7123 | E4: 9280.1507
B5: 0.05 | C5: 12460.567 | D5: 4670.207 | E5: 9057.8393
B6: 0.06 | C6: 12303.842 | D6: 4562.6907 | E6: 8845.3842
B7: 0.07 | C7: 12153.866 | D7: 4460.2541 | E7: 8642.9565
B8: 0.08 | C8: 12010.735 | D8: 4362.9345 | E8: 8450.6219
B9: 0.09 | C9: 11874.476 | D9: 4270.7204 | E9: 8268.3505
B23: Mortality Stress | C23: USA | D23: Japan | E23: India
B24: -0.2 | C24: =0.8*$C$6 -> 9843.0739 | D24: =0.8*D6 -> 3650.1526 | E24: =0.8*E6 -> 7076.3074
B25: -0.1 | C25: =0.9*C6 -> 11073.458 | D25: =0.9*D6 -> 4106.4217 | E25: =0.9*E6 -> 7960.8458
B26: 0 | C26: =C6 -> 12303.842 | D26: =D6 -> 4562.6907 | E26: =E6 -> 8845.3842
B27: 0.1 | C27: =1.1*C6 -> 13534.227 | D27: =1.1*D6 -> 5018.9598 | E27: =1.1*E6 -> 9729.9226
B28: 0.2 | C28: =1.2*C6 -> 14764.611 | D28: =1.2*D6 -> 5475.2289 | E28: =1.2*E6 -> 10614.461
